Workbook

Sheet Premissas
A1: Memória de cálculo — retorno de US$ 100.000 seguindo as recomendações
A2: Reproduz o cálculo do dashboard · período 12/01/2026 a 30/09/2026 · 319 operações
A4: Capital base (US$) | B4: 100000 | C4: ← edite aqui: toda a planilha recalcula
A6: Regra de dimensionamento (piso de cada faixa, definido pelo Rafa)
A7: Perfil | B7: Critério | C7: Sizing
A8: MACDLE Premium | B8: MACDLE, ① CORE, Prob ≥70%, PF ≥1,51 | C8: 0.14
A9: MACD | B9: MACDLE, CORE/CTRL, Prob ≥60%, PF 1,40–1,70 | C9: 0.1
A10: MACDLE CTRL Regular | B10: MACDLE, ② CTRL, Prob 60–69%, PF 1,40–1,60 | C10: 0.085
A11: CP v11 MEDIUM Melhor | B11: CP v11, ◆ MEDIUM, Score 55–64, PF ≥1,30 | C11: 0.08
A12: CP v11 MEDIUM Normal | B12: CP v11, ◆ MEDIUM, Score ≥65, PF ≥1,30 | C12: 0.07
A13: CP v11 STRONG Premium | B13: CP v11, ⬆ STRONG, Score ≥85, PF ≥2,00 | C13: 0.06
A14: Cauteloso / PF ausente | B14: PF ausente, prob baixa ou sinal incompleto | C14: 0.035
A15: Evitar | B15: Regras mandam não operar | C15: 0
A17: Regras aplicadas (as mesmas do dashboard público)
A18: 1. O perfil de cada operação vem da função classifyTradeProfile do worker — a mesma que o dashboard usa.
A19: 2. O capital gira: cada operação usa seu % nominal sobre a base, independentemente de quantas estavam abertas.
A20: 3. Resultado BRUTO: sem corretagem, sem slippage, sem impostos.
A21: 4. Regime IWM: desde 28/09/2026, entradas feitas com o IWM em baixa recebem sizing 0 (coluna 'Regime IWM' = sim na aba Operações).
A22: 5. As operações são reais e foram registradas automaticamente; o dimensionamento é aplicado retroativamente. NÃO é extrato de corretora.
A23: 6. O mês corrente fica fora do acumulado, como no dashboard. Primeiro mês parcial (começa em 12/01).

Sheet Operações
A1: # | B1: Símbolo | C1: Estratégia | D1: Classe | E1: Score | F1: Prob % | G1: PF | H1: Entrada | I1: Saída | J1: Dias | K1: P/L % | L1: Perfil de convicção | M1: Sizing % | N1: Alocação US$ | O1: Contribuição US$ | P1: Acumulado US$ | Q1: Regime IWM
A2: 1 | B2: AXP | C2: sem etiqueta | D2: — | F2: 0.418 | G2: 1.368 | H2: 46027 | I2: 46034 | J2: 7 | K2: -0.0535 | L2: Cauteloso / PF ausente | M2: =IF(Q2="sim",0,IFERROR(INDEX(Premissas!$C$8:$C$15,MATCH(L2,Premissas!$A$8:$A$15,0)),0)) -> 0.035 | N2: =Premissas!$B$4*M2 -> 3500 | O2: =N2*K2 -> -187.25 | P2: =O2 -> -187.25 | Q2: não
A3: 2 | B3: GEV | C3: sem etiqueta | D3: — | F3: 0.4286 | H3: 46024 | I3: 46034 | J3: 10 | K3: -0.0572 | L3: Cauteloso / PF ausente | M3: =IF(Q3="sim",0,IFERROR(INDEX(Premissas!$C$8:$C$15,MATCH(L3,Premissas!$A$8:$A$15,0)),0)) -> 0.035 | N3: =Premissas!$B$4*M3 -> 3500 | O3: =N3*K3 -> -200.2 | P3: =P2+O3 -> -387.45 | Q3: não
A4: 3 | B4: LION | C4: sem etiqueta | D4: — | F4: 0.4211 | H4: 46031 | I4: 46034 | J4: 3 | K4: 0 | L4: Cauteloso / PF ausente | M4: =IF(Q4="sim",0,IFERROR(INDEX(Premissas!$C$8:$C$15,MATCH(L4,Premissas!$A$8:$A$15,0)),0)) -> 0.035 | N4: =Premissas!$B$4*M4 -> 3500 | O4: =N4*K4 -> 0 | P4: =P3+O4 -> -387.45 | Q4: não
A5: 4 | B5: WDC | C5: sem etiqueta | D5: — | F5: 0.6073 | G5: 1.062 | H5: 46034 | I5: 46034 | J5: 0 | K5: 0 | L5: Cauteloso / PF ausente | M5: =IF(Q5="sim",0,IFERROR(INDEX(Premissas!$C$8:$C$15,MATCH(L5,Premissas!$A$8:$A$15,0)),0)) -> 0.035 | N5: =Premissas!$B$4*M5 -> 3500 | O5: =N5*K5 -> 0 | P5: =P4+O5 -> -387.45 | Q5: não
A6: 5 | B6: PHAR | C6: sem etiqueta | D6: — | F6: 0.3889 | H6: 46030 | I6: 46034 | J6: 4 | K6: 0.054 | L6: Cauteloso / PF ausente | M6: =IF(Q6="sim",0,IFERROR(INDEX(Premissas!$C$8:$C$15,MATCH(L6,Premissas!$A$8:$A$15,0)),0)) -> 0.035 | N6: =Premissas!$B$4*M6 -> 3500 | O6: =N6*K6 -> 189 | P6: =P5+O6 -> -198.45 | Q6: não
A7: 6 | B7: AU | C7: sem etiqueta | D7: — | F7: 0.5682 | G7: 1.447 | H7: 46027 | I7: 46034 | J7: 7 | K7: 0.0962 | L7: Cauteloso / PF ausente | M7: =IF(Q7="sim",0,IFERROR(INDEX(Premissas!$C$8:$C$15,MATCH(L7,Premissas!$A$8:$A$15,0)),0)) -> 0.035 | N7: =Premissas!$B$4*M7 -> 3500 | O7: =N7*K7 -> 336.7 | P7: =P6+O7 -> 138.25 | Q7: não
A8: 7 | B8: CRM | C8: sem etiqueta | D8: — | F8: 0.5843 | G8: 2.013 | H8: 46029 | I8: 46035 | J8: 6 | K8: -0.0942 | L8: Cauteloso / PF ausente | M8: =IF(Q8="sim",0,IFERROR(INDEX(Premissas!$C$8:$C$15,MATCH(L8,Premissas!$A$8:$A$15,0)),0)) -> 0.035 | N8: =Premissas!$B$4*M8 -> 3500 | O8: =N8*K8 -> -329.7 | P8: =P7+O8 -> -191.45 | Q8: não
A9: 8 | B9: LION | C9: sem etiqueta | D9: — | F9: 0.4211 | H9: 46031 | I9: 46035 | J9: 4 | K9: 0.0089 | L9: Cauteloso / PF ausente | M9: =IF(Q9="sim",0,IFERROR(INDEX(Premissas!$C$8:$C$15,MATCH(L9,Premissas!$A$8:$A$15,0)),0)) -> 0.035 | N9: =Premissas!$B$4*M9 -> 3500 | O9: =N9*K9 -> 31.15 | P9: =P8+O9 -> -160.3 | Q9: não
A10: 9 | B10: GFI | C10: sem etiqueta | D10: — | F10: 0.6294 | G10: 1.171 | H10: 46028 | I10: 46035 | J10: 7 | K10: 0.0572 | L10: Cauteloso / PF ausente | M10: =IF(Q10="sim",0,IFERROR(INDEX(Premissas!$C$8:$C$15,MATCH(L10,Premissas!$A$8:$A$15,0)),0)) -> 0.035 | N10: =Premissas!$B$4*M10 -> 3500 | O10: =N10*K10 -> 200.2 | P10: =P9+O10 -> 39.9 | Q10: não
A11: 10 | B11: SSRM | C11: sem etiqueta | D11: — | F11: 0.6713 | G11: 1.693 | H11: 46034 | I11: 46035 | J11: 1 | K11: 0.0631 | L11: MACD | M11: =IF(Q11="sim",0,IFERROR(INDEX(Premissas!$C$8:$C$15,MATCH(L11,Premissas!$A$8:$A$15,0)),0)) -> 0.1 | N11: =Premissas!$B$4*M11 -> 10000 | O11: =N11*K11 -> 631 | P11: =P10+O11 -> 670.9 | Q11: não
A12: 11 | B12: ALAB | C12: sem etiqueta | D12: — | F12: 0.8333 | H12: 46034 | I12: 46035 | J12: 1 | K12: 0.0628 | L12: Cauteloso / PF ausente | M12: =IF(Q12="sim",0,IFERROR(INDEX(Premissas!$C$8:$C$15,MATCH(L12,Premissas!$A$8:$A$15,0)),0)) -> 0.035 | N12: =Premissas!$B$4*M12 -> 3500 | O12: =N12*K12 -> 219.8 | P12: =P11+O12 -> 890.7 | Q12: não
A13: 12 | B13: FNMA | C13: sem etiqueta | D13: — | F13: 0.5702 | G13: 1.76 | H13: 46031 | I13: 46036 | J13: 5 | K13: -0.0763 | L13: Cauteloso / PF ausente | M13: =IF(Q13="sim",0,IFERROR(INDEX(Premissas!$C$8:$C$15,MATCH(L13,Premissas!$A$8:$A$15,0)),0)) -> 0.035 | N13: =Premissas!$B$4*M13 -> 3500 | O13: =N13*K13 -> -267.05 | P13: =P12+O13 -> 623.65 | Q13: não
A14: 13 | B14: CLF | C14: sem etiqueta | D14: — | F14: 0.5369 | G14: 1.545 | H14: 46034 | I14: 46036 | J14: 2 | K14: 0.0554 | L14: Cauteloso / PF ausente | M14: =IF(Q14="sim",0,IFERROR(INDEX(Premissas!$C$8:$C$15,MATCH(L14,Premissas!$A$8:$A$15,0)),0)) -> 0.035 | N14: =Premissas!$B$4*M14 -> 3500 | O14: =N14*K14 -> 193.9 | P14: =P13+O14 -> 817.55 | Q14: não
A15: 14 | B15: CRSP | C15: sem etiqueta | D15: — | F15: 0.625 | G15: 2.336 | H15: 46036 | I15: 46037 | J15: 1 | K15: -0.048 | L15: Cauteloso / PF ausente | M15: =IF(Q15="sim",0,IFERROR(INDEX(Premissas!$C$8:$C$15,MATCH(L15,Premissas!$A$8:$A$15,0)),0)) -> 0.035 | N15: =Premissas!$B$4*M15 -> 3500 | O15: =N15*K15 -> -168 | P15: =P14+O15 -> 649.55 | Q15: não
A16: 15 | B16: RNR | C16: sem etiqueta | D16: — | F16: 0.3233 | G16: 1.273 | H16: 46030 | I16: 46037 | J16: 7 | K16: -0.0279 | L16: Cauteloso / PF ausente | M16: =IF(Q16="sim",0,IFERROR(INDEX(Premissas!$C$8:$C$15,MATCH(L16,Premissas!$A$8:$A$15,0)),0)) -> 0.035 | N16: =Premissas!$B$4*M16 -> 3500 | O16: =N16*K16 -> -97.65 | P16: =P15+O16 -> 551.9 | Q16: não
A17: 16 | B17: SPG | C17: sem etiqueta | D17: — | F17: 0.3622 | G17: 2.058 | H17: 46036 | I17: 46037 | J17: 1 | K17: -0.0184 | L17: Cauteloso / PF ausente | M17: =IF(Q17="sim",0,IFERROR(INDEX(Premissas!$C$8:$C$15,MATCH(L17,Premissas!$A$8:$A$15,0)),0)) -> 0.035 | N17: =Premissas!$B$4*M17 -> 3500 | O17: =N17*K17 -> -64.4 | P17: =P16+O17 -> 487.5 | Q17: não
A18: 17 | B18: BLK | C18: sem etiqueta | D18: — | F18: 0.453 | G18: 1.4 | H18: 46035 | I18: 46037 | J18: 2 | K18: 0.0536 | L18: Cauteloso / PF ausente | M18: =IF(Q18="sim",0,IFERROR(INDEX(Premissas!$C$8:$C$15,MATCH(L18,Premissas!$A$8:$A$15,0)),0)) -> 0.035 | N18: =Premissas!$B$4*M18 -> 3500 | O18: =N18*K18 -> 187.6 | P18: =P17+O18 -> 675.1 | Q18: não
A19: 18 | B19: PJT | C19: sem etiqueta | D19: — | F19: 0.4583 | G19: 2.122 | H19: 46027 | I19: 46037 | J19: 10 | K19: 0.0501 | L19: Cauteloso / PF ausente | M19: =IF(Q19="sim",0,IFERROR(INDEX(Premissas!$C$8:$C$15,MATCH(L19,Premissas!$A$8:$A$15,0)),0)) -> 0.035 | N19: =Premissas!$B$4*M19 -> 3500 | O19: =N19*K19 -> 175.35 | P19: =P18+O19 -> 850.45 | Q19: não
A20: 19 | B20: APO | C20: sem etiqueta | D20: — | F20: 0.4561 | G20: 1.046 | H20: 46037 | I20: 46038 | J20: 1 | K20: -0.0017 | L20: Cauteloso / PF ausente | M20: =IF(Q20="sim",0,IFERROR(INDEX(Premissas!$C$8:$C$15,MATCH(L20,Premissas!$A$8:$A$15,0)),0)) -> 0.035 | N20: =Premissas!$B$4*M20 -> 3500 | O20: =N20*K20 -> -5.95 | P20: =P19+O20 -> 844.5 | Q20: não
A21: 20 | B21: LLY | C21: sem etiqueta | D21: — | F21: 0.3438 | G21: 1.169 | H21: 46036 | I21: 46038 | J21: 2 | K21: -0.0331 | L21: Cauteloso / PF ausente | M21: =IF(Q21="sim",0,IFERROR(INDEX(Premissas!$C$8:$C$15,MATCH(L21,Premissas!$A$8:$A$15,0)),0)) -> 0.035 | N21: =Premissas!$B$4*M21 -> 3500 | O21: =N21*K21 -> -115.85 | P21: =P20+O21 -> 728.65 | Q21: não
A22: 21 | B22: BPAC3 | C22: sem etiqueta | D22: — | F22: 0.6111 | G22: 1.612 | H22: 46037 | I22: 46038 | J22: 1 | K22: -0.0041 | L22: MACD | M22: =IF(Q22="sim",0,IFERROR(INDEX(Premissas!$C$8:$C$15,MATCH(L22,Premissas!$A$8:$A$15,0)),0)) -> 0.1 | N22: =Premissas!$B$4*M22 -> 10000 | O22: =N22*K22 -> -41 | P22: =P21+O22 -> 687.65 | Q22: não
A23: 22 | B23: SNEX | C23: sem etiqueta | D23: — | F23: 0.5565 | G23: 1.701 | H23: 46027 | I23: 46038 | J23: 11 | K23: 0.0562 | L23: Cauteloso / PF ausente | M23: =IF(Q23="sim",0,IFERROR(INDEX(Premissas!$C$8:$C$15,MATCH(L23,Premissas!$A$8:$A$15,0)),0)) -> 0.035 | N23: =Premissas!$B$4*M23 -> 3500 | O23: =N23*K23 -> 196.7 | P23: =P22+O23 -> 884.35 | Q23: não
A24: 23 | B24: COCO | C24: sem etiqueta | D24: — | F24: 0.6875 | H24: 46042 | I24: 46042 | J24: 0 | K24: 0 | L24: Cauteloso / PF ausente | M24: =IF(Q24="sim",0,IFERROR(INDEX(Premissas!$C$8:$C$15,MATCH(L24,Premissas!$A$8:$A$15,0)),0)) -> 0.035 | N24: =Premissas!$B$4*M24 -> 3500 | O24: =N24*K24 -> 0 | P24: =P23+O24 -> 884.35 | Q24: não
A25: 24 | B25: LULU | C25: sem etiqueta | D25: — | F25: 0.6944 | G25: 3.062 | H25: 46035 | I25: 46042 | J25: 7 | K25: -0.1095 | L25: Cauteloso / PF ausente | M25: =IF(Q25="sim",0,IFERROR(INDEX(Premissas!$C$8:$C$15,MATCH(L25,Premissas!$A$8:$A$15,0)),0)) -> 0.035 | N25: =Premissas!$B$4*M25 -> 3500 | O25: =N25*K25 -> -383.25 | P25: =P24+O25 -> 501.1 | Q25: não
A26: 25 | B26: NVDA | C26: sem etiqueta | D26: — | F26: 0.6949 | G26: 2.301 | H26: 46037 | I26: 46042 | J26: 5 | K26: -0.0477 | L26: Cauteloso / PF ausente | M26: =IF(Q26="sim",0,IFERROR(INDEX(Premissas!$C$8:$C$15,MATCH(L26,Premissas!$A$8:$A$15,0)),0)) -> 0.035 | N26: =Premissas!$B$4*M26 -> 3500 | O26: =N26*K26 -> -166.95 | P26: =P25+O26 -> 334.15 | Q26: não
A27: 26 | B27: OTF | C27: sem etiqueta | D27: — | F27: 0.3333 | H27: 46037 | I27: 46042 | J27: 5 | K27: -0.0462 | L27: Cauteloso / PF ausente | M27: =IF(Q27="sim",0,IFERROR(INDEX(Premissas!$C$8:$C$15,MATCH(L27,Premissas!$A$8:$A$15,0)),0)) -> 0.035 | N27: =Premissas!$B$4*M27 -> 3500 | O27: =N27*K27 -> -161.7 | P27: =P26+O27 -> 172.45 | Q27: não
A28: 27 | B28: IONQ | C28: sem etiqueta | D28: — | F28: 0.7059 | H28: 46034 | I28: 46042 | J28: 8 | K28: 0.0507 | L28: Cauteloso / PF ausente | M28: =IF(Q28="sim",0,IFERROR(INDEX(Premissas!$C$8:$C$15,MATCH(L28,Premissas!$A$8:$A$15,0)),0)) -> 0.035 | N28: =Premissas!$B$4*M28 -> 3500 | O28: =N28*K28 -> 177.45 | P28: =P27+O28 -> 349.9 | Q28: não
A29: 28 | B29: C | C29: sem etiqueta | D29: — | F29: 0.4679 | G29: 1.435 | H29: 46038 | I29: 46043 | J29: 5 | K29: -0.0354 | L29: Cauteloso / PF ausente | M29: =IF(Q29="sim",0,IFERROR(INDEX(Premissas!$C$8:$C$15,MATCH(L29,Premissas!$A$8:$A$15,0)),0)) -> 0.035 | N29: =Premissas!$B$4*M29 -> 3500 | O29: =N29*K29 -> -123.9 | P29: =P28+O29 -> 226 | Q29: não
A30: 29 | B30: COCO | C30: sem etiqueta | D30: — | F30: 0.6875 | H30: 46042 | I30: 46043 | J30: 1 | K30: -0.0059 | L30: Cauteloso / PF ausente | M30: =IF(Q30="sim",0,IFERROR(INDEX(Premissas!$C$8:$C$15,MATCH(L30,Premissas!$A$8:$A$15,0)),0)) -> 0.035 | N30: =Premissas!$B$4*M30 -> 3500 | O30: =N30*K30 -> -20.65 | P30: =P29+O30 -> 205.35 | Q30: não
A31: 30 | B31: DBI | C31: sem etiqueta | D31: — | F31: 0.625 | G31: 0.779 | H31: 46042 | I31: 46043 | J31: 1 | K31: 0.0327 | L31: Cauteloso / PF ausente | M31: =IF(Q31="sim",0,IFERROR(INDEX(Premissas!$C$8:$C$15,MATCH(L31,Premissas!$A$8:$A$15,0)),0)) -> 0.035 | N31: =Premissas!$B$4*M31 -> 3500 | O31: =N31*K31 -> 114.45 | P31: =P30+O31 -> 319.8 | Q31: não
A32: 31 | B32: HROW | C32: sem etiqueta | D32: — | F32: 0.7414 | G32: 1.413 | H32: 46037 | I32: 46043 | J32: 6 | K32: -0.0256 | L32: MACD | M32: =IF(Q32="sim",0,IFERROR(INDEX(Premissas!$C$8:$C$15,MATCH(L32,Premissas!$A$8:$A$15,0)),0)) -> 0.1 | N32: =Premissas!$B$4*M32 -> 10000 | O32: =N32*K32 -> -256 | P32: =P31+O32 -> 63.8 | Q32: não
A33: 32 | B33: CRUS | C33: sem etiqueta | D33: — | F33: 0.6783 | G33: 1.3 | H33: 46028 | I33: 46043 | J33: 15 | K33: 0.0514 | L33: Cauteloso / PF ausente | M33: =IF(Q33="sim",0,IFERROR(INDEX(Premissas!$C$8:$C$15,MATCH(L33,Premissas!$A$8:$A$15,0)),0)) -> 0.035 | N33: =Premissas!$B$4*M33 -> 3500 | O33: =N33*K33 -> 179.9 | P33: =P32+O33 -> 243.7 | Q33: não
A34: 33 | B34: PLAB | C34: sem etiqueta | D34: — | F34: 0.592 | G34: 1.567 | H34: 46038 | I34: 46043 | J34: 5 | K34: 0.0517 | L34: Cauteloso / PF ausente | M34: =IF(Q34="sim",0,IFERROR(INDEX(Premissas!$C$8:$C$15,MATCH(L34,Premissas!$A$8:$A$15,0)),0)) -> 0.035 | N34: =Premissas!$B$4*M34 -> 3500 | O34: =N34*K34 -> 180.95 | P34: =P33+O34 -> 424.65 | Q34: não
A35: 34 | B35: OMAB | C35: sem etiqueta | D35: — | F35: 0.5309 | G35: 0.92 | H35: 46038 | I35: 46043 | J35: 5 | K35: 0.051 | L35: Cauteloso / PF ausente | M35: =IF(Q35="sim",0,IFERROR(INDEX(Premissas!$C$8:$C$15,MATCH(L35,Premissas!$A$8:$A$15,0)),0)) -> 0.035 | N35: =Premissas!$B$4*M35 -> 3500 | O35: =N35*K35 -> 178.5 | P35: =P34+O35 -> 603.15 | Q35: não
A36: 35 | B36: LMND | C36: sem etiqueta | D36: — | F36: 0.7333 | H36: 46043 | I36: 46044 | J36: 1 | K36: 0.0652 | L36: Cauteloso / PF ausente | M36: =IF(Q36="sim",0,IFERROR(INDEX(Premissas!$C$8:$C$15,MATCH(L36,Premissas!$A$8:$A$15,0)),0)) -> 0.035 | N36: =Premissas!$B$4*M36 -> 3500 | O36: =N36*K36 -> 228.2 | P36: =P35+O36 -> 831.35 | Q36: não
A37: 36 | B37: UNH | C37: sem etiqueta | D37: — | F37: 0.4734 | G37: 1.307 | H37: 46024 | I37: 46044 | J37: 20 | K37: 0.05 | L37: Cauteloso / PF ausente | M37: =IF(Q37="sim",0,IFERROR(INDEX(Premissas!$C$8:$C$15,MATCH(L37,Premissas!$A$8:$A$15,0)),0)) -> 0.035 | N37: =Premissas!$B$4*M37 -> 3500 | O37: =N37*K37 -> 175 | P37: =P36+O37 -> 1006.35 | Q37: não
A38: 37 | B38: USCB | C38: sem etiqueta | D38: — | F38: 0.4091 | H38: 46037 | I38: 46044 | J38: 7 | K38: 0.0505 | L38: Cauteloso / PF ausente | M38: =IF(Q38="sim",0,IFERROR(INDEX(Premissas!$C$8:$C$15,MATCH(L38,Premissas!$A$8:$A$15,0)),0)) -> 0.035 | N38: =Premissas!$B$4*M38 -> 3500 | O38: =N38*K38 -> 176.75 | P38: =P37+O38 -> 1183.1 | Q38: não
A39: 38 | B39: NU | C39: sem etiqueta | D39: — | F39: 0.5 | H39: 46042 | I39: 46044 | J39: 2 | K39: 0.0519 | L39: Cauteloso / PF ausente | M39: =IF(Q39="sim",0,IFERROR(INDEX(Premissas!$C$8:$C$15,MATCH(L39,Premissas!$A$8:$A$15,0)),0)) -> 0.035 | N39: =Premissas!$B$4*M39 -> 3500 | O39: =N39*K39 -> 181.65 | P39: =P38+O39 -> 1364.75 | Q39: não
A40: 39 | B40: COO | C40: sem etiqueta | D40: — | F40: 0.4696 | G40: 2.016 | H40: 46038 | I40: 46048 | J40: 10 | K40: -0.0179 | L40: Cauteloso / PF ausente | M40: =IF(Q40="sim",0,IFERROR(INDEX(Premissas!$C$8:$C$15,MATCH(L40,Premissas!$A$8:$A$15,0)),0)) -> 0.035 | N40: =Premissas!$B$4*M40 -> 3500 | O40: =N40*K40 -> -62.65 | P40: =P39+O40 -> 1302.1 | Q40: não
...

Sheet Mês a mês
A1: Resultado mensal — calculado por SUMIFS sobre a aba Operações
A3: Mês | B3: Início | C3: Fim | D3: Operações | E3: Ganhadoras | F3: Acerto % | G3: Resultado US$ | H3: Retorno % | I3: Acumulado %
A4: Jan/2026 | B4: 46023 | C4: 46053 | D4: =COUNTIFS(Operações!$I$2:$I$320,">="&$B4,Operações!$I$2:$I$320,"<="&$C4) -> 65 | E4: =COUNTIFS(Operações!$I$2:$I$320,">="&$B4,Operações!$I$2:$I$320,"<="&$C4,Operações!$K$2:$K$320,">0") -> 31 | F4: =IFERROR(E4/D4,0) -> 0.47692308 | G4: =SUMIFS(Operações!$O$2:$O$320,Operações!$I$2:$I$320,">="&$B4,Operações!$I$2:$I$320,"<="&$C4) -> 2467.1 | H4: =G4/Premissas!$B$4 -> 0.024671 | I4: =H4 -> 0.024671
A5: Fev/2026 | B5: 46054 | C5: 46081 | D5: =COUNTIFS(Operações!$I$2:$I$320,">="&$B5,Operações!$I$2:$I$320,"<="&$C5) -> 80 | E5: =COUNTIFS(Operações!$I$2:$I$320,">="&$B5,Operações!$I$2:$I$320,"<="&$C5,Operações!$K$2:$K$320,">0") -> 49 | F5: =IFERROR(E5/D5,0) -> 0.6125 | G5: =SUMIFS(Operações!$O$2:$O$320,Operações!$I$2:$I$320,">="&$B5,Operações!$I$2:$I$320,"<="&$C5) -> 8877.8 | H5: =G5/Premissas!$B$4 -> 0.088778 | I5: =I4+H5 -> 0.113449
A6: Mar/2026 | B6: 46082 | C6: 46112 | D6: =COUNTIFS(Operações!$I$2:$I$320,">="&$B6,Operações!$I$2:$I$320,"<="&$C6) -> 47 | E6: =COUNTIFS(Operações!$I$2:$I$320,">="&$B6,Operações!$I$2:$I$320,"<="&$C6,Operações!$K$2:$K$320,">0") -> 22 | F6: =IFERROR(E6/D6,0) -> 0.46808511 | G6: =SUMIFS(Operações!$O$2:$O$320,Operações!$I$2:$I$320,">="&$B6,Operações!$I$2:$I$320,"<="&$C6) -> 1589.4 | H6: =G6/Premissas!$B$4 -> 0.015894 | I6: =I5+H6 -> 0.129343
A7: Abr/2026 | B7: 46113 | C7: 46142 | D7: =COUNTIFS(Operações!$I$2:$I$320,">="&$B7,Operações!$I$2:$I$320,"<="&$C7) -> 20 | E7: =COUNTIFS(Operações!$I$2:$I$320,">="&$B7,Operações!$I$2:$I$320,"<="&$C7,Operações!$K$2:$K$320,">0") -> 15 | F7: =IFERROR(E7/D7,0) -> 0.75 | G7: =SUMIFS(Operações!$O$2:$O$320,Operações!$I$2:$I$320,">="&$B7,Operações!$I$2:$I$320,"<="&$C7) -> 7234.35 | H7: =G7/Premissas!$B$4 -> 0.0723435 | I7: =I6+H7 -> 0.2016865
A8: Mai/2026 | B8: 46143 | C8: 46173 | D8: =COUNTIFS(Operações!$I$2:$I$320,">="&$B8,Operações!$I$2:$I$320,"<="&$C8) -> 26 | E8: =COUNTIFS(Operações!$I$2:$I$320,">="&$B8,Operações!$I$2:$I$320,"<="&$C8,Operações!$K$2:$K$320,">0") -> 21 | F8: =IFERROR(E8/D8,0) -> 0.80769231 | G8: =SUMIFS(Operações!$O$2:$O$320,Operações!$I$2:$I$320,">="&$B8,Operações!$I$2:$I$320,"<="&$C8) -> 7257.6 | H8: =G8/Premissas!$B$4 -> 0.072576 | I8: =I7+H8 -> 0.2742625
A9: Jun/2026 | B9: 46174 | C9: 46203 | D9: =COUNTIFS(Operações!$I$2:$I$320,">="&$B9,Operações!$I$2:$I$320,"<="&$C9) -> 31 | E9: =COUNTIFS(Operações!$I$2:$I$320,">="&$B9,Operações!$I$2:$I$320,"<="&$C9,Operações!$K$2:$K$320,">0") -> 18 | F9: =IFERROR(E9/D9,0) -> 0.58064516 | G9: =SUMIFS(Operações!$O$2:$O$320,Operações!$I$2:$I$320,">="&$B9,Operações!$I$2:$I$320,"<="&$C9) -> 3146.2 | H9: =G9/Premissas!$B$4 -> 0.031462 | I9: =I8+H9 -> 0.3057245
A10: Jul/2026 | B10: 46204 | C10: 46234 | D10: =COUNTIFS(Operações!$I$2:$I$320,">="&$B10,Operações!$I$2:$I$320,"<="&$C10) -> 5 | E10: =COUNTIFS(Operações!$I$2:$I$320,">="&$B10,Operações!$I$2:$I$320,"<="&$C10,Operações!$K$2:$K$320,">0") -> 4 | F10: =IFERROR(E10/D10,0) -> 0.8 | G10: =SUMIFS(Operações!$O$2:$O$320,Operações!$I$2:$I$320,">="&$B10,Operações!$I$2:$I$320,"<="&$C10) -> 5443.15 | H10: =G10/Premissas!$B$4 -> 0.0544315 | I10: =I9+H10 -> 0.360156
A11: Ago/2026 | B11: 46235 | C11: 46265 | D11: =COUNTIFS(Operações!$I$2:$I$320,">="&$B11,Operações!$I$2:$I$320,"<="&$C11) -> 15 | E11: =COUNTIFS(Operações!$I$2:$I$320,">="&$B11,Operações!$I$2:$I$320,"<="&$C11,Operações!$K$2:$K$320,">0") -> 10 | F11: =IFERROR(E11/D11,0) -> 0.66666667 | G11: =SUMIFS(Operações!$O$2:$O$320,Operações!$I$2:$I$320,">="&$B11,Operações!$I$2:$I$320,"<="&$C11) -> 1307.75 | H11: =G11/Premissas!$B$4 -> 0.0130775 | I11: =I10+H11 -> 0.3732335
A12: Set/2026 | B12: 46266 | C12: 46295 | D12: =COUNTIFS(Operações!$I$2:$I$320,">="&$B12,Operações!$I$2:$I$320,"<="&$C12) -> 30 | E12: =COUNTIFS(Operações!$I$2:$I$320,">="&$B12,Operações!$I$2:$I$320,"<="&$C12,Operações!$K$2:$K$320,">0") -> 11 | F12: =IFERROR(E12/D12,0) -> 0.36666667 | G12: =SUMIFS(Operações!$O$2:$O$320,Operações!$I$2:$I$320,">="&$B12,Operações!$I$2:$I$320,"<="&$C12) -> -3538.75 | H12: =G12/Premissas!$B$4 -> -0.0353875 | I12: =I11+H12 -> 0.337846
A13: TOTAL | D13: =SUM(D4:D12) -> 319 | E13: =SUM(E4:E12) -> 181 | F13: =IFERROR(E13/D13,0) -> 0.56739812 | G13: =SUM(G4:G12) -> 33784.6 | H13: =G13/Premissas!$B$4 -> 0.337846
A15: Nota: janeiro começa em 12/01. Outubro (mês corrente) não entra, como no dashboard.

Sheet Por perfil
A1: Contribuição por perfil de convicção — SUMIFS sobre a aba Operações
A3: Perfil | B3: Sizing % | C3: Operações | D3: Ganhadoras | E3: Acerto % | F3: P/L médio % | G3: Contribuição US$ | H3: % do total
A4: MACD | B4: =IFERROR(INDEX(Premissas!$C$8:$C$15,MATCH($A4,Premissas!$A$8:$A$15,0)),0) -> 0.1 | C4: =COUNTIF(Operações!$L$2:$L$320,$A4) -> 75 | D4: =COUNTIFS(Operações!$L$2:$L$320,$A4,Operações!$K$2:$K$320,">0") -> 40 | E4: =IFERROR(D4/C4,0) -> 0.53333333 | F4: =IFERROR(SUMIF(Operações!$L$2:$L$320,$A4,Operações!$K$2:$K$320)/C4,0) -> 0.023218667 | G4: =SUMIF(Operações!$L$2:$L$320,$A4,Operações!$O$2:$O$320) -> 17414 | H4: =IFERROR(G4/$G$11,0) -> 0.51544195
A5: Cauteloso / PF ausente | B5: =IFERROR(INDEX(Premissas!$C$8:$C$15,MATCH($A5,Premissas!$A$8:$A$15,0)),0) -> 0.035 | C5: =COUNTIF(Operações!$L$2:$L$320,$A5) -> 175 | D5: =COUNTIFS(Operações!$L$2:$L$320,$A5,Operações!$K$2:$K$320,">0") -> 98 | E5: =IFERROR(D5/C5,0) -> 0.56 | F5: =IFERROR(SUMIF(Operações!$L$2:$L$320,$A5,Operações!$K$2:$K$320)/C5,0) -> 0.012539429 | G5: =SUMIF(Operações!$L$2:$L$320,$A5,Operações!$O$2:$O$320) -> 7680.4 | H5: =IFERROR(G5/$G$11,0) -> 0.22733435
A6: MACDLE Premium | B6: =IFERROR(INDEX(Premissas!$C$8:$C$15,MATCH($A6,Premissas!$A$8:$A$15,0)),0) -> 0.14 | C6: =COUNTIF(Operações!$L$2:$L$320,$A6) -> 16 | D6: =COUNTIFS(Operações!$L$2:$L$320,$A6,Operações!$K$2:$K$320,">0") -> 8 | E6: =IFERROR(D6/C6,0) -> 0.5 | F6: =IFERROR(SUMIF(Operações!$L$2:$L$320,$A6,Operações!$K$2:$K$320)/C6,0) -> 0.012575 | G6: =SUMIF(Operações!$L$2:$L$320,$A6,Operações!$O$2:$O$320) -> 2816.8 | H6: =IFERROR(G6/$G$11,0) -> 0.083375266
A7: CP v11 MEDIUM Melhor | B7: =IFERROR(INDEX(Premissas!$C$8:$C$15,MATCH($A7,Premissas!$A$8:$A$15,0)),0) -> 0.08 | C7: =COUNTIF(Operações!$L$2:$L$320,$A7) -> 16 | D7: =COUNTIFS(Operações!$L$2:$L$320,$A7,Operações!$K$2:$K$320,">0") -> 11 | E7: =IFERROR(D7/C7,0) -> 0.6875 | F7: =IFERROR(SUMIF(Operações!$L$2:$L$320,$A7,Operações!$K$2:$K$320)/C7,0) -> 0.02170625 | G7: =SUMIF(Operações!$L$2:$L$320,$A7,Operações!$O$2:$O$320) -> 2778.4 | H7: =IFERROR(G7/$G$11,0) -> 0.082238653
A8: CP v11 MEDIUM Normal | B8: =IFERROR(INDEX(Premissas!$C$8:$C$15,MATCH($A8,Premissas!$A$8:$A$15,0)),0) -> 0.07 | C8: =COUNTIF(Operações!$L$2:$L$320,$A8) -> 6 | D8: =COUNTIFS(Operações!$L$2:$L$320,$A8,Operações!$K$2:$K$320,">0") -> 6 | E8: =IFERROR(D8/C8,0) -> 1 | F8: =IFERROR(SUMIF(Operações!$L$2:$L$320,$A8,Operações!$K$2:$K$320)/C8,0) -> 0.044933333 | G8: =SUMIF(Operações!$L$2:$L$320,$A8,Operações!$O$2:$O$320) -> 1887.2 | H8: =IFERROR(G8/$G$11,0) -> 0.05585977
A9: CP v11 STRONG Premium | B9: =IFERROR(INDEX(Premissas!$C$8:$C$15,MATCH($A9,Premissas!$A$8:$A$15,0)),0) -> 0.06 | C9: =COUNTIF(Operações!$L$2:$L$320,$A9) -> 10 | D9: =COUNTIFS(Operações!$L$2:$L$320,$A9,Operações!$K$2:$K$320,">0") -> 7 | E9: =IFERROR(D9/C9,0) -> 0.7 | F9: =IFERROR(SUMIF(Operações!$L$2:$L$320,$A9,Operações!$K$2:$K$320)/C9,0) -> 0.02013 | G9: =SUMIF(Operações!$L$2:$L$320,$A9,Operações!$O$2:$O$320) -> 1207.8 | H9: =IFERROR(G9/$G$11,0) -> 0.035750016
A10: Evitar | B10: =IFERROR(INDEX(Premissas!$C$8:$C$15,MATCH($A10,Premissas!$A$8:$A$15,0)),0) -> 0 | C10: =COUNTIF(Operações!$L$2:$L$320,$A10) -> 21 | D10: =COUNTIFS(Operações!$L$2:$L$320,$A10,Operações!$K$2:$K$320,">0") -> 11 | E10: =IFERROR(D10/C10,0) -> 0.52380952 | F10: =IFERROR(SUMIF(Operações!$L$2:$L$320,$A10,Operações!$K$2:$K$320)/C10,0) -> 0.0042238095 | G10: =SUMIF(Operações!$L$2:$L$320,$A10,Operações!$O$2:$O$320) -> 0 | H10: =IFERROR(G10/$G$11,0) -> 0
A11: TOTAL | C11: =SUM(C4:C10) -> 319 | G11: =SUM(G4:G10) -> 33784.6
A13: Observação: operações com Regime IWM = sim aparecem no perfil delas, mas contribuem US$ 0 (sizing 0).

Sheet Sensibilidade
A1: Teste de robustez — e se as operações sem etiqueta fossem todas dimensionadas no mínimo?
A3: 179 das 319 operações são anteriores à etiqueta de estratégia; nelas o perfil foi inferido por probabilidade e profit factor. Se essa inferência estivesse inflando o resultado, forçar TODAS ao menor tamanho não-zero (3,5%) derrubaria o número.
A7: Cenário | B7: Descrição | C7: Resultado US$ | D7: Retorno %
A8: Base | B8: Perfil inferido por prob/PF nas operações sem etiqueta | C8: =SUM(Operações!$O$2:$O$320) -> 33784.6 | D8: =C8/Premissas!$B$4 -> 0.337846
A9: Conservador | B9: Sem etiqueta forçadas a 3,5% (menor sizing não-zero) | C9: =SUMIF(Operações!$C$2:$C$320,"<>sem etiqueta",Operações!$O$2:$O$320)+SUMIF(Operações!$C$2:$C$320,"sem etiqueta",Operações!$K$2:$K$320)*Premissas!$B$4*0.035 -> 30715.75 | D9: =C9/Premissas!$B$4 -> 0.3071575
